Workbook
Name 记录信息: '02_工况输入'!$C$5
Name scenarioName: '02_工况输入'!$C$6
Name scenarioDate: '02_工况输入'!$C$7
Name operator: '02_工况输入'!$C$8
Name 系统与清水参数: '02_工况输入'!$C$9
Name emitterCount: '02_工况输入'!$C$10
Name emitterFlowLph: '02_工况输入'!$C$11
Name densityKgM3: '02_工况输入'!$C$12
Name kinematicViscosityM2s: '02_工况输入'!$C$13
Name 主管: '02_工况输入'!$C$14
Name mainInnerDiameterMm: '02_工况输入'!$C$15
Name mainOuterDiameterMm: '02_工况输入'!$C$16
Name mainLengthM: '02_工况输入'!$C$17
Name mainRoughnessMm: '02_工况输入'!$C$18
Name mainLocalK: '02_工况输入'!$C$19
Name 代表性支管: '02_工况输入'!$C$20
Name lateralInnerDiameterMm: '02_工况输入'!$C$21
Name lateralOuterDiameterMm: '02_工况输入'!$C$22
Name lateralLengthM: '02_工况输入'!$C$23
Name lateralRoughnessMm: '02_工况输入'!$C$24
Name lateralLocalK: '02_工况输入'!$C$25
Name 动态压力与滴头: '02_工况输入'!$C$26
Name sourceDynamicMpa: '02_工况输入'!$C$27
Name fieldP0Mpa: '02_工况输入'!$C$28
Name fieldP1Mpa: '02_工况输入'!$C$29
Name fieldP2Mpa: '02_工况输入'!$C$30
Name fieldP3Mpa: '02_工况输入'!$C$31
Name heightDifferenceM: '02_工况输入'!$C$32
Name downstreamLossMpa: '02_工况输入'!$C$33
Name emitterMinPressureMpa: '02_工况输入'!$C$34
Name emitterMaxPressureMpa: '02_工况输入'!$C$35
Name 减压阀与公共部件: '02_工况输入'!$C$36
Name regulatorSetMpa: '02_工况输入'!$C$37
Name regulatorMinDifferentialMpa: '02_工况输入'!$C$38
Name backflowLossMpa: '02_工况输入'!$C$39
Name filterCleanLossMpa: '02_工况输入'!$C$40
Name filterDirtyLossMpa: '02_工况输入'!$C$41
Name A路部件: '02_工况输入'!$C$42
Name controllerALossMpa: '02_工况输入'!$C$43
Name checkALossMpa: '02_工况输入'!$C$44
Name fittingsALossMpa: '02_工况输入'!$C$45
Name B路部件: '02_工况输入'!$C$46
Name controllerBLossMpa: '02_工况输入'!$C$47
Name venturiLossMpa: '02_工况输入'!$C$48
Name checkBLossMpa: '02_工况输入'!$C$49
Name fittingsBLossMpa: '02_工况输入'!$C$50
Name 肥液: '02_工况输入'!$C$51
Name waterConcentration: '02_工况输入'!$C$52
Name motherConcentration: '02_工况输入'!$C$53
Name targetConcentration: '02_工况输入'!$C$54
Name fertigationDurationMinutes: '02_工况输入'!$C$55
Name unusableResidualL: '02_工况输入'!$C$56
Name measuredSuctionLph: '02_工况输入'!$C$57
Name 文丘里厂家工况: '02_工况输入'!$C$58
Name venturiModel: '02_工况输入'!$C$59
Name venturiSourceReference: '02_工况输入'!$C$60
Name venturiMaxPressureMpa: '02_工况输入'!$C$61
Name venturiMinMotiveLph: '02_工况输入'!$C$62
Name venturiMaxMotiveLph: '02_工况输入'!$C$63
Name venturiCurveP1Mpa: '02_工况输入'!$C$64

Sheet 00_使用说明
A1: 双液源双末端系统 · 独立工程计算工作簿
A2: Excel 2016兼容 · 无宏 · 无外部链接 · 黄色为现场输入 · 蓝色为设计同步值 · 灰色为公式
A4: 项目 | B4: 当前值 | C4: 说明
A5: 工作簿版本 | B5: 2.1.0 | C5: 生成器据此判断是否可安全同步
A6: 设计版本 | B6: 2026-07-25-v5 | C6: 同步后自动更新
A7: 计算模型 | B7: A路清水直通；B路T1/T2压差旁路；L型末端二选一；5个滴灌节点/10只PC滴头；5个喷淋点。 | C7: 不求解任意分支网络
A8: 单位 | B8: L/h、MPa、mm、m、kg/m³、m²/s | C8: 所有输入使用固定单位
A9: 边界 | B9: 计算结果不等于工程验收 | C9: 缺少厂家曲线或动态压力时保持待确认
A10: 工况 | B10: V4双液源双末端边界工况 | C10: 仅用于警示文丘里最低流量风险
A13: 使用顺序
A14: 1 | B14: 先在“02_工况输入”填写黄色单元格。
A15: 2 | B15: A路、B路分别记录运行时动态压力；P1和P2只在B路稳定运行时读取。
A16: 3 | B16: 文丘里须分别核对滴灌施肥与上空喷药的P1/P2、驱动流量和厂家曲线。
A17: 4 | B17: 滴灌冲洗按末端水质恢复；喷药清水置换按喷灌管内容积并计入标签允许载水量。
A18: 5 | B18: “08_结果摘要”和“09_喷灌与模式”用于打印归档；空输入不会被自动编造。

Sheet 01_当前设计基准
A1: 当前设计基准（自动同步）
A2: 蓝色区域来自接口规格事实层。不要在本页修改候选接口或管径；请回到 system-interfaces.xlsx。
A4: 设计项 | B4: 当前值 | C4: 状态/说明
A5: 设计版本 | B5: 2026-07-25-v5 | C5: 来自接口规格工作簿
A6: 核对日期 | B6: 2026-07-25 | C6: 事实层核对日期
A7: 权威拓扑 | B7: 水源→倒流防止器→过滤器→A/B互斥→合流→L型三通选择滴灌/喷淋 | C7: B路在T1/T2之间并联减压主路与文丘里旁路；两路同时通水
A8: 主水路候选接口 | B8: G1/2（俗称4分） | C8: 内牙/外牙及密封待厂家确认
A9: 测压口候选接口 | B9: G1/4（俗称2分） | C9: P0–P5端口形式待厂家确认
A10: 过滤等级 | B10: 120目 | C10: 厂家标称微米待确认
A11: 主管 | B11: 9/12 mm | C11: 内径/外径
A12: 节点支管 | B12: 待确认/12 mm | C12: OD12可更换PE支管；5段
A13: 滴箭毛管 | B13: 3/5 mm | C13: 3/5内径/外径；10条
A14: P0 | B14: 过滤器后、控制器前 | C14: 共用上游动态压力
A15: P1 | B15: T1公共节点 | C15: 减压主路与文丘里旁路共同入口动态压力
... A19: P5 | B19: 最不利上空喷头入口 | C19: 验证喷头工作压力

Sheet 02_工况输入
A1: 工况输入
A2: 只修改黄色C列。空值表示待确认；不要用静态压力代替运行时动态压力。A列为稳定机器字段。
A4: 机器字段 | B4: 输入项 | C4: 数值 | D4: 单位 | E4: 状态 | F4: 填写说明
A5: 记录信息
A6: scenarioName | B6: 工况名称 | C6: v5十滴头/五喷淋点设计 | E6: 边界算例 | F6: 可按现场日期复制另存
A7: scenarioDate | B7: 记录日期 | C7: 2026-07-25 | E7: 待现场填写 | F7: YYYY-MM-DD
A8: operator | B8: 记录人 | E8: 待现场填写
A9: 系统与清水参数
A10: emitterCount | B10: 同时工作滴头数量 N | C10: 10 | D10: 个 | E10: 边界算例 | F10: 只计同一时刻工作的滴头
A11: emitterFlowLph | B11: 单滴头标称流量 q滴头 | C11: 2 | D11: L/h | E11: 边界算例 | F11: 以拟购型号数据表为准
A12: densityKgM3 | B12: 流体密度 ρ | C12: 1000 | D12: kg/m³ | E12: 工程近似 | F12: 20℃清水
A13: kinematicViscosityM2s | B13: 运动黏度 ν | C13: 1.004e-06 | D13: m²/s | E13: 工程近似 | F13: 20℃清水
A14: 主管
A15: mainInnerDiameterMm | B15: 主管实际内径 | C15: 9 | D15: mm | E15: 候选设计 | F15: 来自9/12候选管
A16: mainOuterDiameterMm | B16: 主管外径 | C16: 12 | D16: mm | E16: 候选设计 | F16: 用于接头匹配
A17: mainLengthM | B17: 主管长度 | C17: 10 | D17: m | E17: 边界算例 | F17: 待按现场修改
A18: mainRoughnessMm | B18: 主管绝对粗糙度 ε | C18: 0 | D18: mm | E18: 边界算例 | F18: 非层流时应采用材料数据
A19: mainLocalK | B19: 主管局部阻力系数 ΣK | C19: 0 | E19: 边界算例 | F19: 确认忽略时明确填0
A20: 代表性支管
A21: lateralInnerDiameterMm | B21: 毛管实际内径 | C21: 3 | D21: mm | E21: 候选设计 | F21: 来自3/5候选管
A22: lateralOuterDiameterMm | B22: 毛管外径 | C22: 5 | D22: mm | E22: 候选设计 | F22: 用于倒刺匹配
A23: lateralLengthM | B23: 单条毛管长度 | C23: 1 | D23: m | E23: 边界算例 | F23: 待按现场修改
A24: lateralRoughnessMm | B24: 毛管绝对粗糙度 ε | C24: 0 | D24: mm | E24: 边界算例 | F24: 非层流时应采用材料数据
A25: lateralLocalK | B25: 毛管局部阻力系数 ΣK | C25: 0 | E25: 边界算例 | F25: 确认忽略时明确填0
A26: 动态压力与滴头
A27: sourceDynamicMpa | B27: 水源动态压力 | D27: MPa | E27: 待现场实测 | F27: A/B运行时分别核对
A28: fieldP0Mpa | B28: P0 过滤器后、控制器前 | D28: MPa | E28: 待现场实测
A29: fieldP1Mpa | B29: P1 T1公共节点动态压力 | D29: MPa | E29: 待现场实测 | F29: 减压主路与文丘里旁路共同入口
A30: fieldP2Mpa | B30: P2 T2公共节点动态压力 | D30: MPa | E30: 待现场实测 | F30: 与P1同工况；ΔP只计算一次
A31: fieldP3Mpa | B31: P3 合流后、末端分配前 | D31: MPa | E31: 待现场实测 | F31: 滴灌/喷灌均记录
A32: heightDifferenceM | B32: 滴头相对P4高差 Δz | C32: 0 | D32: m | E32: 边界算例 | F32: 向上为正，向下为负
A33: downstreamLossMpa | B33: 其他下游压损 | C33: 0 | D33: MPa | E33: 边界算例 | F33: 不重复计主管/支管
A34: emitterMinPressureMpa | B34: 滴头最低工作压力 | D34: MPa | E34: 待厂家确认
A35: emitterMaxPressureMpa | B35: 滴头最高工作压力 | D35: MPa | E35: 待厂家确认
A36: 减压阀与公共部件
A37: regulatorSetMpa | B37: 滴灌下游调压器设定压力（可选） | D37: MPa | E37: 待厂家确认
A38: regulatorMinDifferentialMpa | B38: 滴灌下游调压器最小工作压差（可选） | D38: MPa | E38: 待厂家确认
A39: backflowLossMpa | B39: 倒流防止器压损 | D39: MPa | E39: 待厂家确认 | F39: 对应当前流量
A40: filterCleanLossMpa | B40: 过滤器洁净压损 | D40: MPa | E40: 待厂家确认 | F40: 对应当前流量
A41: filterDirtyLossMpa | B41: 过滤器允许堵塞压损 | D41: MPa | E41: 待厂家确认 | F41: 维护上限
...

Sheet 03_管路水力
A1: 管路水力
A2: Darcy–Weisbach；主管按10只滴头总流量，OD12节点支管按每节点2只滴头，3/5毛管按单只滴头。
A4: 项目 | B4: 主管 | C4: OD12节点支管 | D4: 3/5滴箭毛管 | E4: 单位/说明
A5: 设计流量 | B5: ='02_工况输入'!C10*'02_工况输入'!C11 -> 20 | C5: ='02_工况输入'!C11*2 -> 4 | D5: ='02_工况输入'!C11 -> 2 | E5: L/h
A6: 流量 | B6: =B5/3600000 -> 5.5555556e-06 | C6: =C5/3600000 -> 1.1111111e-06 | D6: =D5/3600000 -> 5.5555556e-07 | E6: m³/s
A7: 实际内径 | B7: ='02_工况输入'!C15 -> 9 | C7: =IF('02_工况输入'!C129="","",'02_工况输入'!C129) | D7: ='02_工况输入'!C21 -> 3 | E7: mm
A8: 长度 | B8: ='02_工况输入'!C17 -> 10 | C8: =IF('02_工况输入'!C131="","",'02_工况输入'!C131) | D8: ='02_工况输入'!C23 -> 1 | E8: m
A9: 绝对粗糙度 | B9: ='02_工况输入'!C18 -> 0 | C9: =IF('02_工况输入'!C132="","",'02_工况输入'!C132) | D9: ='02_工况输入'!C24 -> 0 | E9: mm
A10: 局部阻力系数 | B10: ='02_工况输入'!C19 -> 0 | C10: =IF('02_工况输入'!C133="","",'02_工况输入'!C133) | D10: ='02_工况输入'!C25 -> 0 | E10: —
A11: 截面积 | B11: =IF(B7="","",PI()*(B7/1000)^2/4) -> 6.3617251e-05 | C11: =IF(C7="","",PI()*(C7/1000)^2/4) | D11: =IF(D7="","",PI()*(D7/1000)^2/4) -> 7.0685835e-06 | E11: m²
A12: 流速 | B12: =IF(OR(B6="",B11=""),"",B6/B11) -> 0.087327815 | C12: =IF(OR(C6="",C11=""),"",C6/C11) | D12: =IF(OR(D6="",D11=""),"",D6/D11) -> 0.078595034 | E12: m/s
A13: 雷诺数 | B13: =IF(OR(B12="",'02_工况输入'!C13=""),"",B12*(B7/1000)/'02_工况输入'!C13) -> 782.81906 | C13: =IF(OR(C12="",'02_工况输入'!C13=""),"",C12*(C7/1000)/'02_工况输入'!C13) | D13: =IF(OR(D12="",'02_工况输入'!C13=""),"",D12*(D7/1000)/'02_工况输入'!C13) -> 234.84572 | E13: —
A14: 流态 | B14: =IF(B13="","",IF(B13<2300,"层流",IF(B13<=4000,"过渡区","湍流"))) -> 层流 | C14: =IF(C13="","",IF(C13<2300,"层流",IF(C13<=4000,"过渡区","湍流"))) | D14: =IF(D13="","",IF(D13<2300,"层流",IF(D13<=4000,"过渡区","湍流"))) -> 层流 | E14: —
A15: 摩阻系数 | B15: =IF(B13="","",IF(B13<2300,64/B13,IF(B13<=4000,"",0.25/(LOG10((B9/B7)/3.7+5.74/(B13^0.9))^2)))) -> 0.081755802 | C15: =IF(C13="","",IF(C13<2300,64/C13,IF(C13<=4000,"",0.25/(LOG10((C9/C7)/3.7+5.74/(C13^0.9))^2)))) | D15: =IF(D13="","",IF(D13<2300,64/D13,IF(D13<=4000,"",0.25/(LOG10((D9/D7)/3.7+5.74/(D13^0.9))^2)))) -> 0.27251934 | E15: —
A16: 沿程压损 | B16: =IF(OR(B15="",B8="",B7="",B12=""),"",B15*(B8/(B7/1000))*('02_工况输入'!C12*B12^2/2)/1000000) -> 0.00034637877 | C16: =IF(OR(C15="",C8="",C7="",C12=""),"",C15*(C8/(C7/1000))*('02_工况输入'!C12*C12^2/2)/1000000) | D16: =IF(OR(D15="",D8="",D7="",D12=""),"",D15*(D8/(D7/1000))*('02_工况输入'!C12*D12^2/2)/1000000) -> 0.0002805668 | E16: MPa
A17: 局部压损 | B17: =IF(OR(B10="",B12=""),"",B10*('02_工况输入'!C12*B12^2/2)/1000000) | C17: =IF(OR(C10="",C12=""),"",C10*('02_工况输入'!C12*C12^2/2)/1000000) | D17: =IF(OR(D10="",D12=""),"",D10*('02_工况输入'!C12*D12^2/2)/1000000) | E17: MPa
A18: 总压损 | B18: =IF(OR(B16="",B17=""),"",B16+B17) | C18: =IF(OR(C16="",C17=""),"",C16+C17) | D18: =IF(OR(D16="",D17=""),"",D16+D17) | E18: MPa
A19: 管内容积 | B19: =IF(OR(B11="",B8=""),"",B11*B8*1000) -> 0.63617251 | C19: =IF(OR(C11="",C8=""),"",C11*C8*1000) | D19: =IF(OR(D11="",D8=""),"",D11*D8*1000) -> 0.0070685835 | E19: L
A21: 系统总管内容积 | B21: =IF(OR(B19="",C19="",D19=""),"",B19+5*C19+10*D19) | E21: 主管 + 5×节点支管 + 10×毛管

Sheet 04_A路压力预算
A1: A路压力预算
A2: 清水模式分别核对过滤器洁净与允许堵塞工况；结果只反映已录入压损。
A4: 项目 | B4: 洁净工况 | C4: 允许堵塞 | D4: 单位/判断
A5: 水源动态压力 | B5: =IF('02_工况输入'!$C$27=0,"",'02_工况输入'!$C$27) | C5: =IF('02_工况输入'!$C$27=0,"",'02_工况输入'!$C$27) | D5: MPa
A6: 减压阀设定压力 | B6: =IF('02_工况输入'!$C$37=0,"",'02_工况输入'!$C$37) | C6: =IF('02_工况输入'!$C$37=0,"",'02_工况输入'!$C$37) | D6: MPa
A7: 减压阀最小工作压差 | B7: =IF('02_工况输入'!$C$38=0,"",'02_工况输入'!$C$38) | C7: =IF('02_工况输入'!$C$38=0,"",'02_工况输入'!$C$38) | D7: MPa
A8: 公共与A路压损 | B8: =IF(OR('02_工况输入'!$C$39="",'02_工况输入'!$C$40="",'02_工况输入'!$C$43="",'02_工况输入'!$C$44="",'02_工况输入'!$C$45=""),"",'02_工况输入'!$C$39+'02_工况输入'!$C$40+'02_工况输入'!$C$43+'02_工况输入'!$C$44+'02_工况输入'!$C$45) | C8: =IF(OR('02_工况输入'!$C$39="",'02_工况输入'!$C$41="",'02_工况输入'!$C$43="",'02_工况输入'!$C$44="",'02_工况输入'!$C$45=""),"",'02_工况输入'!$C$39+'02_工况输入'!$C$41+'02_工况输入'!$C$43+'02_工况输入'!$C$44+'02_工况输入'!$C$45) | D8: MPa
A9: 所需水源压力 | B9: =IF(OR(B6="",B7="",B8=""),"",B6+B7+B8) | C9: =IF(OR(C6="",C7="",C8=""),"",C6+C7+C8) | D9: MPa
A10: 动态压力余量 | B10: =IF(OR(B5="",B9=""),"",B5-B9) | C10: =IF(OR(C5="",C9=""),"",C5-C9) | D10: MPa
A11: 压力预算状态 | B11: =IF(B10="","待确认",IF(B10>=0,"已计算","不适用")) -> 待确认 | C11: =IF(C10="","待确认",IF(C10>=0,"已计算","不适用")) -> 待确认 | D11: 余量≥0方可满足已录入条件
A12: 说明 | B12: 缺少任一厂家压损时保持待确认 | C12: 堵塞压损达到维护上限时核对 | D12: 支路止回阀不代替水源倒流防护

Sheet 05_B路与文丘里
A1: B路压差旁路与文丘里判定
A2: T1/T2间减压主路与文丘里旁路同时通水。实际驱动流量必须实测；P1-P2压差只计一次。
A4: 项目 | B4: 实际/设计值 | C4: 厂家下限 | D4: 厂家上限/曲线 | E4: 状态或公式
A5: P1（T1） | B5: =IF('02_工况输入'!C29="","",'02_工况输入'!C29) | E5: MPa
A6: P2（T2） | B6: =IF('02_工况输入'!C30="","",'02_工况输入'!C30) | E6: MPa
A7: ΔP旁路 | B7: =IF(OR(B5="",B6=""),"",B5-B6) | E7: P1-P2
A8: 下游设计总流量 | B8: ='02_工况输入'!C10*'02_工况输入'!C11 -> 20 | E8: L/h；不是文丘里驱动流量
A9: 目标吸液量 | B9: =IF('06_肥液与桶'!B8="","",'06_肥液与桶'!B8) | E9: L/h
A10: 实际文丘里驱动流量 | B10: =IF('02_工况输入'!C127="","",'02_工况输入'!C127) | E10: L/h；同工况实测
A11: 文丘里最大工作压力 | B11: =IF('02_工况输入'!C62="","",'02_工况输入'!C62) | E11: MPa
A12: 允许驱动流量 | B12: =IF('02_工况输入'!C63="","",'02_工况输入'!C63) | D12: =IF('02_工况输入'!C64="","",'02_工况输入'!C64) | E12: L/h
A13: 厂家曲线P1 | B13: =IF('02_工况输入'!C65="","",'02_工况输入'!C65) | E13: MPa
A14: 厂家曲线P2 | B14: =IF('02_工况输入'!C66="","",'02_工况输入'!C66) | E14: MPa
A15: 厂家曲线驱动流量 | B15: =IF('02_工况输入'!C67="","",'02_工况输入'!C67) | E15: L/h
A16: 厂家曲线吸液量 | B16: =IF('02_工况输入'!C68="","",'02_工况输入'!C68) | E16: L/h
A17: 资料确认 | B17: =IF('02_工况输入'!C69="","",'02_工况输入'!C69) | E17: TRUE后仍需现场清水调试
A18: 文丘里适用性 | B18: =IF(B17<>TRUE,"待厂家确认",IF(OR(B5="",B6="",B7="",B10="",B11="",C12="",D12="",D13="",D14="",D15="",D16=""),"待确认",IF(OR(B7<=0,B5>B11,B10<C12,B10>D12,B9>D16),"不适用","已计算"))) -> 待厂家确认 | E18: P1≤P2不适用；缺驱动流量/曲线待确认

Sheet 06_肥液与桶
A1: 肥液、吸液量与桶容量
A2: 三种浓度必须使用同一单位；本表不判断肥料溶解度和材料兼容性。
A4: 项目 | B4: 数值 | C4: 单位 | D4: 公式/说明
A5: Q设计 | B5: ='03_管路水力'!B5 -> 20 | C5: L/h | D5: N×q滴头
A6: 清水背景浓度 | B6: ='02_工况输入'!$C$52 -> 0 | C6: 同单位 | D6: C水
A7: 母液浓度 | B7: =IF('02_工况输入'!$C$53=0,"",'02_工况输入'!$C$53) | C7: 同单位 | D7: C母液
A8: 目标浓度 | B8: =IF('02_工况输入'!$C$54=0,"",'02_工况输入'!$C$54) | C8: 同单位 | D8: C目标
A9: B路时间 | B9: =IF('02_工况输入'!$C$55=0,"",'02_工况输入'!$C$55) | C9: min
A10: 目标吸液量 | B10: =IF(OR(B7="",B8=""),"",IF(OR(B7<=B6,B8<B6,B8>=B7),"",B5*(B8-B6)/(B7-B6))) | C10: L/h | D10: Q设计×(C目标-C水)/(C母液-C水)
A11: 清水总量（非文丘里驱动量） | B11: =IF(OR(B5="",B8=""),"",B5-B8) | C11: L/h | D11: 下游清水质量平衡；不得视为文丘里实际驱动流量
A12: 本周期母液量 | B12: =IF(OR(B10="",B9=""),"",B10*B9/60) | C12: L | D12: q吸×t/60
A13: 不可吸残余量 | B13: ='02_工况输入'!$C$56 -> 0 | C13: L
A14: 最低有效桶容量 | B14: =IF(B12="","",B12+B13) | C14: L | D14: 母液量+残余量

Sheet 07_冲洗与均匀度
A1: 冲洗时间与滴头均匀度
A2: 理论冲洗时间仅代表一个管内容积；采样数必须为4的倍数，最终冲洗终点仍按末端水质确认。
A4: 序号 | B4: 采样体积mL | C4: 换算流量L/h | D4: 低四分位辅助值 | E4: 输入/结果 | F4: 说明
A5: 1 | B5: =IF('02_工况输入'!$C$72=0,"",'02_工况输入'!$C$72) | C5: =IF(OR(B5="",'02_工况输入'!$C$71<=0),"",B5*60/(1000*'02_工况输入'!$C$71)) | D5: =IF(ROW()-4<=COUNT('02_工况输入'!$C$72:$C$87)/4,SMALL($C$5:$C$20,ROW()-4),"")
A6: 2 | B6: =IF('02_工况输入'!$C$73=0,"",'02_工况输入'!$C$73) | C6: =IF(OR(B6="",'02_工况输入'!$C$71<=0),"",B6*60/(1000*'02_工况输入'!$C$71)) | D6: =IF(ROW()-4<=COUNT('02_工况输入'!$C$72:$C$87)/4,SMALL($C$5:$C$20,ROW()-4),"")
A7: 3 | B7: =IF('02_工况输入'!$C$74=0,"",'02_工况输入'!$C$74) | C7: =IF(OR(B7="",'02_工况输入'!$C$71<=0),"",B7*60/(1000*'02_工况输入'!$C$71)) | D7: =IF(ROW()-4<=COUNT('02_工况输入'!$C$72:$C$87)/4,SMALL($C$5:$C$20,ROW()-4),"")
A8: 4 | B8: =IF('02_工况输入'!$C$75=0,"",'02_工况输入'!$C$75) | C8: =IF(OR(B8="",'02_工况输入'!$C$71<=0),"",B8*60/(1000*'02_工况输入'!$C$71)) | D8: =IF(ROW()-4<=COUNT('02_工况输入'!$C$72:$C$87)/4,SMALL($C$5:$C$20,ROW()-4),"")
A9: 5 | B9: =IF('02_工况输入'!$C$76=0,"",'02_工况输入'!$C$76) | C9: =IF(OR(B9="",'02_工况输入'!$C$71<=0),"",B9*60/(1000*'02_工况输入'!$C$71)) | D9: =IF(ROW()-4<=COUNT('02_工况输入'!$C$72:$C$87)/4,SMALL($C$5:$C$20,ROW()-4),"")
A10: 6 | B10: =IF('02_工况输入'!$C$77=0,"",'02_工况输入'!$C$77) | C10: =IF(OR(B10="",'02_工况输入'!$C$71<=0),"",B10*60/(1000*'02_工况输入'!$C$71)) | D10: =IF(ROW()-4<=COUNT('02_工况输入'!$C$72:$C$87)/4,SMALL($C$5:$C$20,ROW()-4),"")
A11: 7 | B11: =IF('02_工况输入'!$C$78=0,"",'02_工况输入'!$C$78) | C11: =IF(OR(B11="",'02_工况输入'!$C$71<=0),"",B11*60/(1000*'02_工况输入'!$C$71)) | D11: =IF(ROW()-4<=COUNT('02_工况输入'!$C$72:$C$87)/4,SMALL($C$5:$C$20,ROW()-4),"")
A12: 8 | B12: =IF('02_工况输入'!$C$79=0,"",'02_工况输入'!$C$79) | C12: =IF(OR(B12="",'02_工况输入'!$C$71<=0),"",B12*60/(1000*'02_工况输入'!$C$71)) | D12: =IF(ROW()-4<=COUNT('02_工况输入'!$C$72:$C$87)/4,SMALL($C$5:$C$20,ROW()-4),"")
A13: 9 | B13: =IF('02_工况输入'!$C$80=0,"",'02_工况输入'!$C$80) | C13: =IF(OR(B13="",'02_工况输入'!$C$71<=0),"",B13*60/(1000*'02_工况输入'!$C$71)) | D13: =IF(ROW()-4<=COUNT('02_工况输入'!$C$72:$C$87)/4,SMALL($C$5:$C$20,ROW()-4),"")
A14: 10 | B14: =IF('02_工况输入'!$C$81=0,"",'02_工况输入'!$C$81) | C14: =IF(OR(B14="",'02_工况输入'!$C$71<=0),"",B14*60/(1000*'02_工况输入'!$C$71)) | D14: =IF(ROW()-4<=COUNT('02_工况输入'!$C$72:$C$87)/4,SMALL($C$5:$C$20,ROW()-4),"")
A15: 11 | B15: =IF('02_工况输入'!$C$82=0,"",'02_工况输入'!$C$82) | C15: =IF(OR(B15="",'02_工况输入'!$C$71<=0),"",B15*60/(1000*'02_工况输入'!$C$71)) | D15: =IF(ROW()-4<=COUNT('02_工况输入'!$C$72:$C$87)/4,SMALL($C$5:$C$20,ROW()-4),"")
A16: 12 | B16: =IF('02_工况输入'!$C$83=0,"",'02_工况输入'!$C$83) | C16: =IF(OR(B16="",'02_工况输入'!$C$71<=0),"",B16*60/(1000*'02_工况输入'!$C$71)) | D16: =IF(ROW()-4<=COUNT('02_工况输入'!$C$72:$C$87)/4,SMALL($C$5:$C$20,ROW()-4),"")
A17: 13 | B17: =IF('02_工况输入'!$C$84=0,"",'02_工况输入'!$C$84) | C17: =IF(OR(B17="",'02_工况输入'!$C$71<=0),"",B17*60/(1000*'02_工况输入'!$C$71)) | D17: =IF(ROW()-4<=COUNT('02_工况输入'!$C$72:$C$87)/4,SMALL($C$5:$C$20,ROW()-4),"")
A18: 14 | B18: =IF('02_工况输入'!$C$85=0,"",'02_工况输入'!$C$85) | C18: =IF(OR(B18="",'02_工况输入'!$C$71<=0),"",B18*60/(1000*'02_工况输入'!$C$71)) | D18: =IF(ROW()-4<=COUNT('02_工况输入'!$C$72:$C$87)/4,SMALL($C$5:$C$20,ROW()-4),"")
A19: 15 | B19: =IF('02_工况输入'!$C$86=0,"",'02_工况输入'!$C$86) | C19: =IF(OR(B19="",'02_工况输入'!$C$71<=0),"",B19*60/(1000*'02_工况输入'!$C$71)) | D19: =IF(ROW()-4<=COUNT('02_工况输入'!$C$72:$C$87)/4,SMALL($C$5:$C$20,ROW()-4),"")
A20: 16 | B20: =IF('02_工况输入'!$C$87=0,"",'02_工况输入'!$C$87) | C20: =IF(OR(B20="",'02_工况输入'!$C$71<=0),"",B20*60/(1000*'02_工况输入'!$C$71)) | D20: =IF(ROW()-4<=COUNT('02_工况输入'!$C$72:$C$87)/4,SMALL($C$5:$C$20,ROW()-4),"")
A23: 结果
A24: 系统总管内容积 | B24: ='03_管路水力'!B21 -> 0 | C24: L | F24: 来自管路水力
A25: 实测冲洗总流量 | B25: =IF('02_工况输入'!$C$70=0,"",'02_工况输入'!$C$70) | C25: L/h | F25: 现场输入
A26: 理论冲洗时间 | B26: =IF(OR(B24="",B25<=0),"",B24/B25*60) | C26: min | F26: 一个管内容积
A27: 平均滴头流量 | B27: =IF(COUNT('02_工况输入'!$C$72:$C$87)<4,"",AVERAGE(C5:C20)) | C27: L/h
A28: 最低四分位平均/DUlq | B28: =IF(OR(COUNT('02_工况输入'!$C$72:$C$87)<4,MOD(COUNT('02_工况输入'!$C$72:$C$87),4)<>0),"",AVERAGE(D5:D20)) | C28: L/h | E28: =IF(OR(B27="",B28=""),"",B28/B27) | F28: %

Sheet 08_结果摘要
A1: 当前工况结果摘要
A2: 本页适合打印归档。任何“已计算”只说明输入足够执行公式，不替代厂家选型和现场验收。
A4: 指标 | B4: 结果 | C4: 单位 | D4: 状态 | E4: 下一步
A5: 系统设计流量 | B5: ='03_管路水力'!B5 -> 20 | C5: L/h | D5: =IF(B5="","待确认",IF(OR(B5="不适用",B5="待厂家确认",B5="待确认"),B5,"已计算")) -> 已计算 | E5: 核对同时工作滴头数
A6: 系统管内容积 | B6: ='03_管路水力'!B21 -> 0 | C6: L | D6: =IF(B6="","待确认",IF(OR(B6="不适用",B6="待厂家确认",B6="待确认"),B6,"已计算")) -> 待确认 | E6: 用于冲洗时间
A7: A路洁净压力余量 | B7: ='04_A路压力预算'!B10 | C7: MPa | D7: =IF(B7="","待确认",IF(OR(B7="不适用",B7="待厂家确认",B7="待确认"),B7,"已计算")) -> 待确认 | E7: 运行时测水源动态压力
A8: A路堵塞压力余量 | B8: ='04_A路压力预算'!C10 | C8: MPa | D8: =IF(B8="","待确认",IF(OR(B8="不适用",B8="待厂家确认",B8="待确认"),B8,"已计算")) -> 待确认 | E8: 达到过滤器维护上限前清洗
A9: 文丘里实测压差 | B9: =IF('05_B路与文丘里'!B18<>"已计算","",'05_B路与文丘里'!B7) | C9: MPa | D9: =IF(B9="","待确认",IF(OR(B9="不适用",B9="待厂家确认",B9="待确认"),B9,"已计算")) -> 待确认 | E9: B路稳定后读取P1、P2
A10: 文丘里适用性 | B10: ='05_B路与文丘里'!B18 -> 待厂家确认 | D10: =IF(B10="","待确认",IF(OR(B10="不适用",B10="待厂家确认",B10="待确认"),B10,"已计算")) -> 待厂家确认 | E10: 缺厂家曲线时不得采购判定
A11: 最低有效桶容量 | B11: =IF('06_肥液与桶'!B10="","",'06_肥液与桶'!B14) | C11: L | D11: =IF(B11="","待确认",IF(OR(B11="不适用",B11="待厂家确认",B11="待确认"),B11,"已计算")) -> 待确认 | E11: 另行考虑安全余量
A12: 理论冲洗时间 | B12: ='07_冲洗与均匀度'!B26 | C12: min | D12: =IF(B12="","待确认",IF(OR(B12="不适用",B12="待厂家确认",B12="待确认"),B12,"已计算")) -> 待确认 | E12: 末端水质恢复后才停止
A13: DUlq | B13: =IF(COUNT('02_工况输入'!$C$72:$C$87)<4,"",'07_冲洗与均匀度'!E28) | C13: % | D13: =IF(B13="","待确认",IF(OR(B13="不适用",B13="待厂家确认",B13="待确认"),B13,"已计算")) -> 待确认 | E13: 按项目目标判断
A16: 安全边界
A17: 文丘里验收边界 | B17: 滴灌和喷淋分别记录实际驱动流量、P1/P2及厂家同工况曲线
A18: 首次施肥 | B18: 先用清水完成动态压力、反向窜流、总流量、吸液量和均匀度测试。

Sheet _meta
A1: fertigation-baseline:v2
A2: cb42fa86327d852f7ca749d6377734c6f08741f8b8621312dc8d31cd75ae87e5
A3: 2026-07-25-v5

Sheet 09_喷灌与模式
A1: 喷淋、喷药与模式合同
A2: 喷淋按5个点计算；切换末端前必须关闭A/B并泄压，停止模式不要求L型末端阀关闭。
A4: 项目 | B4: 结果 | C4: 单位 | D4: 状态 | E4: 公式/判定 | F4: 下一步
A5: 操作原则 | B5: 先关闭A/B并泄压，再切换L型末端阀；停止时末端阀可保持原位 | D5: 禁止T型三通双末端同时连通 | E5: 两只三通手动选择阀 | F5: 按阀位卡核对 MV-END、MV-SOURCE 与 A/B 程序
A6: 模式合同 | B6: 停止/清水滴灌/滴灌施肥/清水喷淋/上空喷药 | D6: L型末端二选一 + 液源三位 | E6: 每只三通阀仅允许一个锁定位置 | F6: 禁止使用无中位全关或会内部串通的三通阀
A7: 滴灌设计流量 | B7: ='02_工况输入'!C10*'02_工况输入'!C11 -> 20 | D7: L/h；10只PC滴头 | E7: N×q滴头 | F7: 核对滴头数量
A8: 喷淋设计流量 | B8: =IF(OR('02_工况输入'!C90="",'02_工况输入'!C91=""),"",'02_工况输入'!C90*'02_工况输入'!C91) | D8: L/h；5个喷淋点 | E8: M×q喷头 | F8: 核对喷头数量与覆盖
A9: 喷淋主管总压损 | B9: ='07_冲洗与均匀度'!B13 | D9: MPa | E9: πD²L/4 | F9: 用于清水置换
A10: 最不利喷头可用压力 | B10: =IF(OR('02_工况输入'!C31="",B9="",'02_工况输入'!C97="",'02_工况输入'!C98="",'02_工况输入'!C105=""),"",'02_工况输入'!C31-B9-'02_工况输入'!C97-'02_工况输入'!C98-'02_工况输入'!C105-0.00980665*'02_工况输入'!C96) | D10: MPa | E10: Q/A | F10: 核对管径
A11: 喷头压力状态 | B11: =IF(B10="","待确认",IF(OR('02_工况输入'!C99="",'02_工况输入'!C100=""),"待确认",IF(AND(B10>='02_工况输入'!C99,B10<='02_工况输入'!C100),"已计算","不适用"))) -> 待确认 | D11: 缺厂家范围/实测=待确认 | E11: vD/ν
A12: 喷淋清水置换体积 | B12: ='07_冲洗与均匀度'!B20 -> 0 | D12: L | E12: 层流/过渡区/湍流
A13: 喷淋清水置换时间 | B13: ='07_冲洗与均匀度'!B21 -> 0 | D13: min | E13: 64/Re或Swamee–Jain
E14: f(L/D)ρv²/2
A15: 喷药目标吸液量 | B15: =IF(OR(B8="",'02_工况输入'!C108="",'02_工况输入'!C109="",'02_工况输入'!C110=""),"",B8*('02_工况输入'!C110-'02_工况输入'!C108)/('02_工况输入'!C109-'02_工况输入'!C110)) | D15: L/h | E15: ΣKρv²/2
A16: 喷药所需清水试桶体积 | B16: =IF(OR(B15="",'02_工况输入'!C111=""),"",B15*'02_工况输入'!C111/60+'02_工况输入'!C112) | D16: L | E16: 沿程＋局部
A17: 喷药标签确认 | B17: ='02_工况输入'!C116 -> 0 | D17: TRUE后仍须清水调试 | E17: 现场动态压力 | F17: 核对喷头范围
A18: 喷药实际吸液流量 | B18: ='02_工况输入'!C113 -> 0 | D18: L/h | E18: Pmin≤P5≤Pmax
A19: 喷药实际文丘里驱动流量 | B19: ='02_工况输入'!C128 -> 0 | D19: L/h；不得用喷淋总流量代替 | E19: 由用户录入的浓度平衡 | F19: 不自动推荐剂量
A20: 喷药工况ΔP | B20: =IF(OR('02_工况输入'!C106="",'02_工况输入'!C107=""),"",'02_工况输入'!C106-'02_工况输入'!C107) | D20: P1-P2 | E20: Q喷灌-q吸
A21: 喷药文丘里适用性 | B21: =IF(B17<>TRUE,"待厂家确认",IF(OR(B15="",B18="",B19="",'02_工况输入'!C118="",'02_工况输入'!C119="",'02_工况输入'!C120="",'02_工况输入'!C121=""),"待确认",IF(OR(B20<=0,B19<'02_工况输入'!C63,B19>'02_工况输入'!C64,B15>'02_工况输入'!C121),"不适用","已计算"))) -> 待厂家确认 | D21: P1≤P2不适用；缺驱动流量/曲线待确认 | E21: 喷药工况动态压差
E22: 标签＋厂家工况＋现场水力 | F22: 缺任一项保持待确认
A23: 交叉禁用 | B23: 肥料不得进入喷淋；农药不得进入滴灌 | D23: 运行前人工复核 | E23: V喷灌/Q清水×60 | F23: 计入标签允许载水量
A24: 停止合同 | B24: A/B全关、液源关闭；末端阀可保持滴灌或喷淋位 | D24: 停止不再要求末端关闭 | E24: 只提供工程水力 | F24: 按登记标签执行
